<?xml version="1.0" ?>
<!-- =================================================================================== -->
<!-- |    This document was autogenerated by xacro from rrbot_ros2.xacro                    | -->
<!-- |    EDITING THIS FILE BY HAND IS NOT RECOMMENDED                                 | -->
<!-- =================================================================================== -->
<!-- Revolute-Revolute Manipulator -->
<robot name="rrbot_ros2">
 
 <!-- plugin -->
  <gazebo>
    <plugin name="rrbot_ros2_plugin" filename="librrbot_ros2_plugin.so">
    <update_rate>1000</update_rate> <!--Number of times per second a plugin information is taken within Gazebo. (1000times/sec)-->

      <!-- necessary? -->
      <joint_name>joint1</joint_name>
      <joint_name>joint2</joint_name>
      <joint_name>joint3</joint_name>

    </plugin>
  </gazebo>


  <!-- Link1 -->
  <gazebo reference="link1">
    <material>Gazebo/Green</material>
  </gazebo>

  <!-- Link2 -->
  <gazebo reference="link2">
    <mu1>0.2</mu1>
    <mu2>0.2</mu2>
    <material>Gazebo/Black</material>
  </gazebo>
  
  <!-- Link3 -->
  <gazebo reference="link3">
    <mu1>0.2</mu1>
    <mu2>0.2</mu2>
    <material>Gazebo/Orange</material>
  </gazebo>

  <!-- gazebo rgba -->
  <material name="black">
    <color rgba="0.0 0.0 0.0 1.0"/>
  </material>
  <material name="blue">
    <color rgba="0.0 0.0 0.8 1.0"/>
  </material>
  <material name="green">
    <color rgba="0.0 0.8 0.0 1.0"/>
  </material>
  <material name="grey">
    <color rgba="0.2 0.2 0.2 1.0"/>
  </material>
  <material name="orange">
    <color rgba="1.0 0.4235294117647059 0.0392156862745098 1.0"/>
  </material>
  <material name="brown">
    <color rgba="0.8705882352941177 0.8117647058823529 0.7647058823529411 1.0"/>
  </material>
  <material name="red">
    <color rgba="0.8 0.0 0.0 1.0"/>
  </material>
  <material name="white">
    <color rgba="1.0 1.0 1.0 1.0"/>
  </material>

  <!-- Used for fixing robot to Gazebo 'base_link' -->
  <link name="world"/>
  <joint name="fixed" type="fixed">
    <parent link="world"/>
    <child link="base"/>
    <origin xyz="0 0 0" rpy="0 0 0"/>
    <axis xyz="0 0 1"/>
    <dynamics damping="0.7"/>
  </joint>

  
  <!-- Base Link -->
  <link name="base">
    <collision>
      <origin rpy="0 0 0" xyz="0 0 0.125"/>
      <geometry>
        <cylinder length="0.25" radius="0.05"/>
      </geometry>
    </collision>
    <visual>
      <origin rpy="0 0 0" xyz="0 0 0.125"/>
      <geometry>
        <cylinder length="0.25" radius="0.05"/>
      </geometry>
      <material name="orange"/>
    </visual>
    <inertial>
      <origin rpy="0 0 0" xyz="0 0 0.125"/>
      <mass value="1"/>
      <inertia ixx="0.005833333333333334" ixy="0.0" ixz="0.0" iyy="0.005833333333333334" iyz="0.0" izz="0.0006250000000000001"/>
    </inertial>
  </link>

<!-- joint1 -->
  <joint name="joint1" type="continuous">
    <parent link="base"/>
    <child link="link1"/>
    <origin rpy="0 0 0" xyz="0 0 0.25"/>
    <axis xyz="0 0 1"/>
    <dynamics damping="0.7"/>
  </joint>
  
  
  <link name="link1">
    <!-- Sphere -->
    <collision>
      <origin rpy="0 0 0" xyz="0 0 0"/>
      <geometry>
        <sphere radius="0.06"/>
      </geometry>
    </collision>
    <visual>
      <origin rpy="0 0 0" xyz="0 0 0"/>
      <geometry>
        <sphere radius="0.06"/>
      </geometry>
      <material name="Black"/>
    </visual>
    <inertial>
      <origin rpy="0 0 0" xyz="0 0 0"/>
      <mass value="1"/>
      <inertia ixx="0.001" ixy="0.0" ixz="0.0" iyy="0.001" iyz="0.0" izz="0.001"/>
    </inertial>
    <!-- Cylinder -->
    <collision>
      <origin rpy="0 0 0" xyz="0 0 0.125"/>
      <geometry>
        <cylinder length="0.25" radius="0.05"/>
      </geometry>
    </collision>
    <visual>
      <origin rpy="0 0 0" xyz="0 0 0.125"/>
      <geometry>
        <cylinder length="0.25" radius="0.05"/>
      </geometry>
      <material name="orange"/>
    </visual>
    <inertial>
      <origin rpy="0 0 0" xyz="0 0 0.125"/>
      <mass value="1"/>
      <inertia ixx="0.005833333333333334" ixy="0.0" ixz="0.0" iyy="0.005833333333333334" iyz="0.0" izz="0.0006250000000000001"/>
    </inertial>
  </link>

<!-- joint2 -->
  <joint name="joint2" type="continuous">
    <parent link="link1"/>
    <child link="link2"/>
    <origin rpy="0 0 0" xyz="0 0 0.25"/>
    <axis xyz="0 1 0"/>
    <dynamics damping="0.7"/>
  </joint>



  <!-- Middle Link -->
  <link name="link2">
    <!-- Sphere -->
    <collision>
      <origin rpy="0 0 0" xyz="0 0 0"/>
      <geometry>
        <sphere radius="0.06"/>
      </geometry>
    </collision>
    <visual>
      <origin rpy="0 0 0" xyz="0 0 0"/>
      <geometry>
        <sphere radius="0.06"/>
      </geometry>
      <material name="orange"/>
    </visual>
    <inertial>
      <origin rpy="0 0 0" xyz="0 0 0"/>
      <mass value="1"/>
      <inertia ixx="0.001" ixy="0.0" ixz="0.0" iyy="0.001" iyz="0.0" izz="0.001"/>
    </inertial>
    <!-- Cylinder -->
    <collision>
      <origin rpy="0 0 0" xyz="0 0 0.5"/>
      <geometry>
        <cylinder length="1" radius="0.05"/>
      </geometry>
    </collision>
    <visual>
      <origin rpy="0 0 0" xyz="0 0 0.5"/>
      <geometry>
        <cylinder length="1" radius="0.05"/>
      </geometry>
      <material name="black"/>
    </visual>
    <inertial>
      <origin rpy="0 0 0" xyz="0 0 0.5"/>
      <mass value="1"/>
      <inertia ixx="0.08395833333333333" ixy="0.0" ixz="0.0" iyy="0.08395833333333333" iyz="0.0" izz="0.0006250000000000001"/>
    </inertial>
  </link>


<!-- joint3 -->
  <joint name="joint3" type="continuous">
    <parent link="link2"/>
    <child link="link3"/>
    <origin rpy="0 0 0" xyz="0 0 1"/>
    <axis xyz="0 1 0"/>
    <dynamics damping="0.7"/>
  </joint>



  <!-- Top Link -->
  <link name="link3">
    <!-- Sphere -->
    <collision>
      <origin rpy="0 0 0" xyz="0 0 0"/>
      <geometry>
        <sphere radius="0.06"/>
      </geometry>
    </collision>
    <visual>
      <origin rpy="0 0 0" xyz="0 0 0"/>
      <geometry>
        <sphere radius="0.06"/>
      </geometry>
      <material name="orange"/>
    </visual>
    <inertial>
      <origin rpy="0 0 0" xyz="0 0 0"/>
      <mass value="1"/>
      <inertia ixx="0.001" ixy="0.0" ixz="0.0" iyy="0.001" iyz="0.0" izz="0.001"/>
    </inertial>
    <!-- Cylinder -->
    <collision>
      <origin rpy="0 0 0" xyz="0 0 0.5"/>
      <geometry>
        <cylinder length="1" radius="0.05"/>
      </geometry>
    </collision>
    <visual>
      <origin rpy="0 0 0" xyz="0 0 0.5"/>
      <geometry>
        <cylinder length="1" radius="0.05"/>
      </geometry>
      <material name="orange"/>
    </visual>
    <inertial>
      <origin rpy="0 0 0" xyz="0 0 0.5"/>
      <mass value="1"/>
      <inertia ixx="0.08395833333333333" ixy="0.0" ixz="0.0" iyy="0.08395833333333333" iyz="0.0" izz="0.0006250000000000001"/>
    </inertial>
  </link>

<!-- joint4 -->
  <joint name="end_effector_fixed" type="fixed">
    <parent link="link3"/>
    <child link="end_effector"/>
    <origin rpy="0 0 0" xyz="0 0 1"/>
  </joint>


  <!-- End_effector -->
  <link name="end_effector">
    <collision>
      <origin rpy="0 0 0" xyz="0 0 0.03125"/>
      <geometry>
        <box size="0.1 0.1 0.0625"/>
      </geometry>
    </collision>
    <visual>
      <origin rpy="0 0 0" xyz="0 0 0.03125"/>
      <geometry>
        <box size="0.1 0.1 0.0625"/>
      </geometry>
      <material name="orange"/>
    </visual>
    <inertial>
      <origin rpy="0 0 0" xyz="0 0 0.03125"/>
      <mass value="0"/>
      <inertia ixx="0.00052" ixy="0.0" ixz="0.0" iyy="0.00052" iyz="0.0" izz="0.0008"/>
    </inertial>
    <collision>
      <origin rpy="0 0 0" xyz="0 0.07 0.125"/>
      <geometry>
        <box size="0.05 0.05 0.25"/>
      </geometry>
    </collision>
    <visual>
      <origin rpy="0 0 0" xyz="0 0.07 0.125"/>
      <geometry>
        <box size="0.05 0.05 0.25"/>
      </geometry>
      <material name="orange"/>
    </visual>
    <inertial>
      <origin rpy="0 0 0" xyz="0 0.07 0.125"/>
      <mass value="0"/>
      <inertia ixx="0.0002" ixy="0.0" ixz="0.0" iyy="0.0002" iyz="0.0" izz="0.0004"/>
    </inertial>
    <collision>
      <origin rpy="0 0 0" xyz="0 -0.07 0.125"/>
      <geometry>
        <box size="0.05 0.05 0.25"/>
      </geometry>
    </collision>
    <visual>
      <origin rpy="0 0 0" xyz="0 -0.07 0.125"/>
      <geometry>
        <box size="0.05 0.05 0.25"/>
      </geometry>
      <material name="orange"/>
    </visual>
    <inertial>
      <origin rpy="0 0 0" xyz="0 -0.07 0.125"/>
      <mass value="0"/>
      <inertia ixx="0.0002" ixy="0.0" ixz="0.0" iyy="0.0002" iyz="0.0" izz="0.0004"/>
    </inertial>
  </link>

</robot>