<?xml version="1.0" ?>
<!-- =================================================================================== -->
<!-- |    This document was autogenerated by xacro from rrbot.xacro                    | -->
<!-- |    EDITING THIS FILE BY HAND IS NOT RECOMMENDED                                 | -->
<!-- =================================================================================== -->
<!-- Revolute-Revolute Manipulator -->
<robot name="rrbot">
  <!-- Space btw top of beam and the each joint -->
  <!-- ros_control plugin -->
  <!-- <gazebo>
    <plugin filename="libgazebo_ros_control.so" name="gazebo_ros_control">
      <robotNamespace>/rrbot</robotNamespace>
      <robotSimType>gazebo_ros_control/DefaultRobotHWSim</robotSimType>
    </plugin>
  </gazebo> -->

  <!-- Link1 -->
  <gazebo reference="link1">
    <material>Gazebo/Green</material>
  </gazebo>
  <!-- Link2 -->
  <gazebo reference="link2">
    <mu1>0.2</mu1>
    <mu2>0.2</mu2>
    <material>Gazebo/Black</material>
  </gazebo>
  
  <!-- Link3 -->
  <gazebo reference="link3">
    <mu1>0.2</mu1>
    <mu2>0.2</mu2>
    <material>Gazebo/Orange</material>
  </gazebo>
  <material name="black">
    <color rgba="0.0 0.0 0.0 1.0"/>
  </material>
  <material name="blue">
    <color rgba="0.0 0.0 0.8 1.0"/>
  </material>
  <material name="green">
    <color rgba="0.0 0.8 0.0 1.0"/>
  </material>
  <material name="grey">
    <color rgba="0.2 0.2 0.2 1.0"/>
  </material>
  <material name="orange">
    <color rgba="1.0 0.4235294117647059 0.0392156862745098 1.0"/>
  </material>
  <material name="brown">
    <color rgba="0.8705882352941177 0.8117647058823529 0.7647058823529411 1.0"/>
  </material>
  <material name="red">
    <color rgba="0.8 0.0 0.0 1.0"/>
  </material>
  <material name="white">
    <color rgba="1.0 1.0 1.0 1.0"/>
  </material>
  <!-- Used for fixing robot to Gazebo 'base_link' -->
  <link name="world"/>
  <joint name="fixed" type="fixed">
    <parent link="world"/>
    <child link="base"/>
    <!-- <origin xyz="0 0 0" rpy="0 0 0"/>
    <axis xyz="0 0 1"/>
    <dynamics damping="0.7"/> -->
  </joint>
  <!-- Base Link -->
  <link name="base">
    <collision>
      <origin rpy="0 0 0" xyz="0 0 0.125"/>
      <geometry>
        <cylinder length="0.25" radius="0.05"/>
      </geometry>
    </collision>
    <visual>
      <origin rpy="0 0 0" xyz="0 0 0.125"/>
      <geometry>
        <cylinder length="0.25" radius="0.05"/>
      </geometry>
      <material name="orange"/>
    </visual>
    <inertial>
      <origin rpy="0 0 0" xyz="0 0 0.125"/>
      <mass value="1"/>
      <inertia ixx="0.005833333333333334" ixy="0.0" ixz="0.0" iyy="0.005833333333333334" iyz="0.0" izz="0.0006250000000000001"/>
    </inertial>
  </link>
  <joint name="joint1" type="continuous">
    <parent link="base"/>
    <child link="link1"/>
    <origin rpy="0 0 0" xyz="0 0 0.25"/>
    <axis xyz="0 0 1"/>
    <dynamics damping="0.7"/>
  </joint>
  <link name="link1">
    <!-- Sphere -->
    <collision>
      <origin rpy="0 0 0" xyz="0 0 0"/>
      <geometry>
        <sphere radius="0.06"/>
      </geometry>
    </collision>
    <visual>
      <origin rpy="0 0 0" xyz="0 0 0"/>
      <geometry>
        <sphere radius="0.06"/>
      </geometry>
      <material name="Black"/>
    </visual>
    <inertial>
      <origin rpy="0 0 0" xyz="0 0 0"/>
      <mass value="1"/>
      <inertia ixx="0.001" ixy="0.0" ixz="0.0" iyy="0.001" iyz="0.0" izz="0.001"/>
    </inertial>
    <!-- Cylinder -->
    <collision>
      <origin rpy="0 0 0" xyz="0 0 0.125"/>
      <geometry>
        <cylinder length="0.25" radius="0.05"/>
      </geometry>
    </collision>
    <visual>
      <origin rpy="0 0 0" xyz="0 0 0.125"/>
      <geometry>
        <cylinder length="0.25" radius="0.05"/>
      </geometry>
      <material name="orange"/>
    </visual>
    <inertial>
      <origin rpy="0 0 0" xyz="0 0 0.125"/>
      <mass value="1"/>
      <inertia ixx="0.005833333333333334" ixy="0.0" ixz="0.0" iyy="0.005833333333333334" iyz="0.0" izz="0.0006250000000000001"/>
    </inertial>
  </link>
  <joint name="joint2" type="continuous">
    <parent link="link1"/>
    <child link="link2"/>
    <origin rpy="0 0 0" xyz="0 0 0.25"/>
    <axis xyz="0 1 0"/>
    <dynamics damping="0.7"/>
  </joint>
  <!-- Middle Link -->
  <link name="link2">
    <!-- Sphere -->
    <collision>
      <origin rpy="0 0 0" xyz="0 0 0"/>
      <geometry>
        <sphere radius="0.06"/>
      </geometry>
    </collision>
    <visual>
      <origin rpy="0 0 0" xyz="0 0 0"/>
      <geometry>
        <sphere radius="0.06"/>
      </geometry>
      <material name="orange"/>
    </visual>
    <inertial>
      <origin rpy="0 0 0" xyz="0 0 0"/>
      <mass value="1"/>
      <inertia ixx="0.001" ixy="0.0" ixz="0.0" iyy="0.001" iyz="0.0" izz="0.001"/>
    </inertial>
    <!-- Cylinder -->
    <collision>
      <origin rpy="0 0 0" xyz="0 0 0.5"/>
      <geometry>
        <cylinder length="1" radius="0.05"/>
      </geometry>
    </collision>
    <visual>
      <origin rpy="0 0 0" xyz="0 0 0.5"/>
      <geometry>
        <cylinder length="1" radius="0.05"/>
      </geometry>
      <material name="black"/>
    </visual>
    <inertial>
      <origin rpy="0 0 0" xyz="0 0 0.5"/>
      <mass value="1"/>
      <inertia ixx="0.08395833333333333" ixy="0.0" ixz="0.0" iyy="0.08395833333333333" iyz="0.0" izz="0.0006250000000000001"/>
    </inertial>
  </link>
  <joint name="joint3" type="continuous">
    <parent link="link2"/>
    <child link="link3"/>
    <origin rpy="0 0 0" xyz="0 0 1"/>
    <axis xyz="0 1 0"/>
    <dynamics damping="0.7"/>
  </joint>
  <!-- Top Link -->
  <link name="link3">
    <!-- Sphere -->
    <collision>
      <origin rpy="0 0 0" xyz="0 0 0"/>
      <geometry>
        <sphere radius="0.06"/>
      </geometry>
    </collision>
    <visual>
      <origin rpy="0 0 0" xyz="0 0 0"/>
      <geometry>
        <sphere radius="0.06"/>
      </geometry>
      <material name="orange"/>
    </visual>
    <inertial>
      <origin rpy="0 0 0" xyz="0 0 0"/>
      <mass value="1"/>
      <inertia ixx="0.001" ixy="0.0" ixz="0.0" iyy="0.001" iyz="0.0" izz="0.001"/>
    </inertial>
    <!-- Cylinder -->
    <collision>
      <origin rpy="0 0 0" xyz="0 0 0.5"/>
      <geometry>
        <cylinder length="1" radius="0.05"/>
      </geometry>
    </collision>
    <visual>
      <origin rpy="0 0 0" xyz="0 0 0.5"/>
      <geometry>
        <cylinder length="1" radius="0.05"/>
      </geometry>
      <material name="orange"/>
    </visual>
    <inertial>
      <origin rpy="0 0 0" xyz="0 0 0.5"/>
      <mass value="1"/>
      <inertia ixx="0.08395833333333333" ixy="0.0" ixz="0.0" iyy="0.08395833333333333" iyz="0.0" izz="0.0006250000000000001"/>
    </inertial>
  </link>
  <joint name="end_effector_fixed" type="fixed">
    <parent link="link3"/>
    <child link="end_effector"/>
    <origin rpy="0 0 0" xyz="0 0 1"/>
  </joint>
  <!-- End_effector -->
  <link name="end_effector">
    <collision>
      <origin rpy="0 0 0" xyz="0 0 0.03125"/>
      <geometry>
        <box size="0.1 0.1 0.0625"/>
      </geometry>
    </collision>
    <visual>
      <origin rpy="0 0 0" xyz="0 0 0.03125"/>
      <geometry>
        <box size="0.1 0.1 0.0625"/>
      </geometry>
      <material name="orange"/>
    </visual>
    <inertial>
      <origin rpy="0 0 0" xyz="0 0 0.03125"/>
      <mass value="0"/>
      <inertia ixx="0.00052" ixy="0.0" ixz="0.0" iyy="0.00052" iyz="0.0" izz="0.0008"/>
    </inertial>
    <collision>
      <origin rpy="0 0 0" xyz="0 0.07 0.125"/>
      <geometry>
        <box size="0.05 0.05 0.25"/>
      </geometry>
    </collision>
    <visual>
      <origin rpy="0 0 0" xyz="0 0.07 0.125"/>
      <geometry>
        <box size="0.05 0.05 0.25"/>
      </geometry>
      <material name="orange"/>
    </visual>
    <inertial>
      <origin rpy="0 0 0" xyz="0 0.07 0.125"/>
      <mass value="0"/>
      <inertia ixx="0.0002" ixy="0.0" ixz="0.0" iyy="0.0002" iyz="0.0" izz="0.0004"/>
    </inertial>
    <collision>
      <origin rpy="0 0 0" xyz="0 -0.07 0.125"/>
      <geometry>
        <box size="0.05 0.05 0.25"/>
      </geometry>
    </collision>
    <visual>
      <origin rpy="0 0 0" xyz="0 -0.07 0.125"/>
      <geometry>
        <box size="0.05 0.05 0.25"/>
      </geometry>
      <material name="orange"/>
    </visual>
    <inertial>
      <origin rpy="0 0 0" xyz="0 -0.07 0.125"/>
      <mass value="0"/>
      <inertia ixx="0.0002" ixy="0.0" ixz="0.0" iyy="0.0002" iyz="0.0" izz="0.0004"/>
    </inertial>
  </link>

  <!-- <hardwareInterface>hardware_interface/EffortJointInterface</hardwareInterface> -->
  <!-- <transmission name="tran1">
    <type>transmission_interface/SimpleTransmission</type>
    <joint name="joint1">
      <hardwareInterface>hardware_interface/PositionJointInterface</hardwareInterface>
    </joint>
    <actuator name="motor1">
      <hardwareInterface>hardware_interface/PositionJointInterface</hardwareInterface>
      <mechanicalReduction>1</mechanicalReduction>
    </actuator>
  </transmission>
  <transmission name="tran2">
    <type>transmission_interface/SimpleTransmission</type>
    <joint name="joint2">
      <hardwareInterface>hardware_interface/PositionJointInterface</hardwareInterface>
    </joint>
    <actuator name="motor2">
      <hardwareInterface>hardware_interface/PositionJointInterface</hardwareInterface>
      <mechanicalReduction>1</mechanicalReduction>
    </actuator>
  </transmission>
  <transmission name="tran3">
    <type>transmission_interface/SimpleTransmission</type>
    <joint name="joint3">
      <hardwareInterface>hardware_interface/PositionJointInterface</hardwareInterface>
    </joint>
    <actuator name="motor3">
      <hardwareInterface>hardware_interface/PositionJointInterface</hardwareInterface>
      <mechanicalReduction>1</mechanicalReduction>
    </actuator>
  </transmission> -->

  <!--////////////////////////////////   plugin    ////////////////////////////////-->
  <!-- <gazebo>
    <plugin name="arm_plugin" filename="libarm_plugin.so">
    </plugin>
  </gazebo> -->

  <!-- <gazebo>
    <plugin filename="libgazebo_ros2_control.so" name="gazebo_ros2_control">
      <robot_param>robot_description</robot_param>
      <robot_param_node>robot_state_publisher</robot_param_node>
      <parameters>$(find rifo_gazebo2)/config/rrbot_control2.yaml</parameters>
      <controller_manager_name>simulation_controller_manager</controller_manager_name>
    </plugin>
  </gazebo> -->

    <!-- <ros2_control name="RRBotSystemPositionOnly" type="system">
    <hardware>
      <plugin>ros2_control_demo_hardware/RRBotSystemPositionOnlyHardware</plugin>
    </hardware>
    <joint name="joint1">
      <command_interface name="position">
        <param name="min">-1</param>
        <param name="max">1</param>
      </command_interface>
      <state_interface name="position"/>
    </joint>
    <joint name="joint2">
      <command_interface name="position">
        <param name="min">-1</param>
        <param name="max">1</param>
      </command_interface>
      <state_interface name="position"/>
    </joint>
    <joint name="joint3">
      <command_interface name="position">
        <param name="min">-1</param>
        <param name="max">1</param>
      </command_interface>
      <state_interface name="position"/>
    </joint>
  </ros2_control> -->

  <gazebo>
      <plugin name="gazebo_ros2_control" filename="libgazebo_ros2_control.so">
        <parameters>$(find rifo_gazebo2)/config/rrbot_control2.yaml</parameters>
      </plugin>
    </gazebo>

  <ros2_control name="rrbot_ros2_control" type="system">
      <hardware>
        <plugin>ros2_control_demo_example_1/RRBotSystemPositionOnlyHardware</plugin>
        <param name="example_param_hw_start_duration_sec">0</param>
        <param name="example_param_hw_stop_duration_sec">3.0</param>
        <param name="example_param_hw_slowdown">100</param>
      </hardware>

      <joint name="joint1">
        <command_interface name="position">
          <param name="min">-1</param>
          <param name="max">1</param>
        </command_interface>
        <state_interface name="position"/>
      </joint>
      <joint name="joint2">
        <command_interface name="position">
          <param name="min">-1</param>
          <param name="max">1</param>
        </command_interface>
        <state_interface name="position"/>
      </joint>
    </ros2_control>

</robot>
