<?xml version="1.0"?>
<robot xmlns:xacro="http://www.ros.org/wiki/xacro">

  <xacro:macro name="rrbot" params="parent prefix *origin">

  <!-- Constants for robot dimensions -->
  <xacro:property name="mass" value="1" /> <!-- arbitrary value for mass -->
  <xacro:property name="width" value="0.1" /> <!-- Square dimensions (widthxwidth) of beams -->
  <xacro:property name="l1" value="0.25" /> <!-- Link 1 -->
  <xacro:property name="l2" value="1" /> <!-- Link 2 -->
  <xacro:property name="l3" value="1" /> <!-- Link 3 -->
  <xacro:property name="axel_offset" value="0.05" /> <!-- Space btw top of beam and the each joint -->

  <joint name="${prefix}base_joint" type="fixed">
    <xacro:insert_block name="origin" />
    <parent link="${parent}"/>
    <child link="${prefix}base_link" />
  </joint>

  <!-- Base Link -->
  <link name="${prefix}base_link">
    <collision>
      <origin xyz="0 0 ${l1/2}" rpy="0 0 0"/>
      <geometry>
        <box size="${width} ${width} ${l1}"/>
      </geometry>
    </collision>

    <visual>
      <origin xyz="0 0 ${l1/2}" rpy="0 0 0"/>
      <geometry>
        <box size="${width} ${width} ${l1}"/>
      </geometry>
      <material name="orange"/>
    </visual>

    <inertial>
      <origin xyz="0 0 ${l1/2}" rpy="0 0 0"/>
      <mass value="${mass}"/>
      <inertia
        ixx="${mass / 12.0 * (width*width + l1*l1)}" ixy="0.0" ixz="0.0"
        iyy="${mass / 12.0 * (l1*l1 + width*width)}" iyz="0.0"
        izz="${mass / 12.0 * (width*width + width*width)}"/>
      </inertial>
    </link>

    <joint name="${prefix}joint1" type="continuous">
      <parent link="${prefix}base_link"/>
      <child link="${prefix}link1"/>
      <origin xyz="0 0 ${l1}" rpy="0 0 0"/>
      <axis xyz="0 0 1"/>
      <dynamics damping="0.7"/>
    </joint>

    <!-- Middle Link -->
    <link name="${prefix}link1">
      <collision>
        <origin xyz="0 0 ${l1/2}" rpy="0 0 0"/>
        <geometry>
          <box size="${width} ${width} ${l1}"/>
        </geometry>
      </collision>

      <visual>
        <origin xyz="0 0 ${l1/2}" rpy="0 0 0"/>
        <geometry>
          <box size="${width} ${width} ${l1}"/>
        </geometry>
        <material name="yellow"/>
      </visual>

      <inertial>
        <origin xyz="0 0 ${l2/2}" rpy="0 0 0"/>
        <mass value="${mass}"/>
        <inertia
          ixx="${mass / 12.0 * (width*width + l2*l2)}" ixy="0.0" ixz="0.0"
          iyy="${mass / 12.0 * (l2*l2 + width*width)}" iyz="0.0"
          izz="${mass / 12.0 * (width*width + width*width)}"/>
        </inertial>
      </link>

      <joint name="${prefix}joint2" type="continuous">
        <parent link="${prefix}link1"/>
        <child link="${prefix}link2"/>
        <origin xyz="0 0 ${l1}" rpy="0 0 0"/>
        <axis xyz="0 1 0"/>
        <dynamics damping="0.7"/>
      </joint>

    <!-- Middle Link -->
    <link name="${prefix}link2">
      <collision>
        <origin xyz="0 0 ${l2/2}" rpy="0 0 0"/>
        <geometry>
          <box size="${width} ${width} ${l2}"/>
        </geometry>
      </collision>

      <visual>
        <origin xyz="0 0 ${l2/2}" rpy="0 0 0"/>
        <geometry>
          <box size="${width} ${width} ${l2}"/>
        </geometry>
        <material name="orange"/>
      </visual>

      <inertial>
        <origin xyz="0 0 ${l2/2}" rpy="0 0 0"/>
        <mass value="${mass}"/>
        <inertia
          ixx="${mass / 12.0 * (width*width + l2*l2)}" ixy="0.0" ixz="0.0"
          iyy="${mass / 12.0 * (l2*l2 + width*width)}" iyz="0.0"
          izz="${mass / 12.0 * (width*width + width*width)}"/>
        </inertial>
      </link>

      <joint name="${prefix}joint3" type="continuous">
        <parent link="${prefix}link2"/>
        <child link="${prefix}link3"/>
        <origin xyz="0 0 ${l2}" rpy="0 0 0"/>
        <axis xyz="0 1 0"/>
        <dynamics damping="0.7"/>
      </joint>

      <!-- Top Link -->
      <link name="${prefix}link3">
        <collision>
          <origin xyz="0 0 ${l3/2}" rpy="0 0 0"/>
          <geometry>
            <box size="${width} ${width} ${l3}"/>
          </geometry>
        </collision>

        <visual>
          <origin xyz="0 0 ${l3/2}" rpy="0 0 0"/>
          <geometry>
            <box size="${width} ${width} ${l3}"/>
          </geometry>
          <material name="yellow"/>
        </visual>

        <inertial>
          <origin xyz="0 0 ${l3/2}" rpy="0 0 0"/>
          <mass value="${mass}"/>
          <inertia
            ixx="${mass / 12.0 * (width*width + l3*l3)}" ixy="0.0" ixz="0.0"
            iyy="${mass / 12.0 * (l3*l3 + width*width)}" iyz="0.0"
            izz="${mass / 12.0 * (width*width + width*width)}"/>
          </inertial>
        </link>

  </xacro:macro>

</robot>
